<?xml version="1.0"?>
<robot xmlns:xacro="http://www.ros.org/wiki/xacro">
  <xacro:macro name="thruster" params="name thruster_name *origin ">

    <link name="${name}_base_link">
      <visual>
        <geometry>
          <box size="0.1 0.1 0.3"/>
        </geometry>
        <material name="black"/>
      </visual>
      <inertial>
        <mass value="0.001" />
        <origin xyz="0 0 0" rpy="0 0 0"/>
        <inertia ixx="0.000000017" ixy="0.0" ixz="0.0"
               iyy="0.000000017" iyz="0.0"
               izz="0.000000017" />
      </inertial>
    </link>

    <joint name="${name}_joint" type="continuous" >
      <parent link="base_link" />
      <child link="${name}_base_link" />
      <xacro:insert_block name="origin" />
    </joint>

    <gazebo>
      <plugin name="${name}_thruster_model" filename="libair_thruster_ros_plugin.so">
        <linkName>${name}_base_link</linkName>
         <thrusterName>${thruster_name}</thrusterName>
        <inputTopic>/thrusters/${name}/input</inputTopic>
      </plugin>
    </gazebo>

    <gazebo reference="thruster_${name}">
      <selfCollide>false</selfCollide>
    </gazebo>

  </xacro:macro>
</robot>